[2024-11-29T04:19:54.911+0000] {local_task_job_runner.py:123} INFO - ::group::Pre task execution logs
[2024-11-29T04:19:54.937+0000] {taskinstance.py:2613} INFO - Dependencies all met for dep_context=non-requeueable deps ti=<TaskInstance: ETL_usa_spending.ingest_usa_spending_data_task scheduled__2024-11-28T00:00:00+00:00 [queued]>
[2024-11-29T04:19:54.947+0000] {taskinstance.py:2613} INFO - Dependencies all met for dep_context=requeueable deps ti=<TaskInstance: ETL_usa_spending.ingest_usa_spending_data_task scheduled__2024-11-28T00:00:00+00:00 [queued]>
[2024-11-29T04:19:54.948+0000] {taskinstance.py:2866} INFO - Starting attempt 1 of 1
[2024-11-29T04:19:54.966+0000] {taskinstance.py:2889} INFO - Executing <Task(PythonOperator): ingest_usa_spending_data_task> on 2024-11-28 00:00:00+00:00
[2024-11-29T04:19:54.983+0000] {logging_mixin.py:190} WARNING - /home/***/.local/lib/python3.12/site-packages/***/task/task_runner/standard_task_runner.py:70 DeprecationWarning: This process (pid=45355) is multi-threaded, use of fork() may lead to deadlocks in the child.
[2024-11-29T04:19:54.985+0000] {standard_task_runner.py:72} INFO - Started process 45357 to run task
[2024-11-29T04:19:54.982+0000] {standard_task_runner.py:104} INFO - Running: ['***', 'tasks', 'run', 'ETL_usa_spending', 'ingest_usa_spending_data_task', 'scheduled__2024-11-28T00:00:00+00:00', '--job-id', '462', '--raw', '--subdir', 'DAGS_FOLDER/project_dag.py', '--cfg-path', '/tmp/tmp7_6noqn1']
[2024-11-29T04:19:54.987+0000] {standard_task_runner.py:105} INFO - Job 462: Subtask ingest_usa_spending_data_task
[2024-11-29T04:19:55.053+0000] {task_command.py:467} INFO - Running <TaskInstance: ETL_usa_spending.ingest_usa_spending_data_task scheduled__2024-11-28T00:00:00+00:00 [running]> on host 6a246d8d590f
[2024-11-29T04:19:55.449+0000] {taskinstance.py:3132} INFO - Exporting env vars: AIRFLOW_CTX_DAG_OWNER='***' AIRFLOW_CTX_DAG_ID='ETL_usa_spending' AIRFLOW_CTX_TASK_ID='ingest_usa_spending_data_task' AIRFLOW_CTX_EXECUTION_DATE='2024-11-28T00:00:00+00:00' AIRFLOW_CTX_TRY_NUMBER='1' AIRFLOW_CTX_DAG_RUN_ID='scheduled__2024-11-28T00:00:00+00:00'
[2024-11-29T04:19:55.453+0000] {taskinstance.py:731} INFO - ::endgroup::
[2024-11-29T04:19:55.990+0000] {logging_mixin.py:190} INFO - Checking for new data to ingest into states
[2024-11-29T04:20:17.082+0000] {logging_mixin.py:190} INFO - Error fetching existing data from states: connection to server at "database-1.cfwk0mcqm9mf.us-east-2.rds.amazonaws.com" (18.218.251.218), port 5432 failed: Connection refused
	Is the server running on that host and accepting TCP/IP connections?
[2024-11-29T04:20:17.083+0000] {logging_mixin.py:190} INFO - Ingesting new data into states
[2024-11-29T04:20:59.206+0000] {logging_mixin.py:190} INFO - Error: connection to server at "database-1.cfwk0mcqm9mf.us-east-2.rds.amazonaws.com" (18.218.251.218), port 5432 failed: Connection refused
	Is the server running on that host and accepting TCP/IP connections?
connection to server at "database-1.cfwk0mcqm9mf.us-east-2.rds.amazonaws.com" (18.218.251.218), port 5432 failed: Connection refused
	Is the server running on that host and accepting TCP/IP connections?
[2024-11-29T04:20:59.511+0000] {logging_mixin.py:190} INFO - Checking for new data to ingest into cfdaprograms
[2024-11-29T04:21:41.631+0000] {logging_mixin.py:190} INFO - Error fetching existing data from cfdaprograms: connection to server at "database-1.cfwk0mcqm9mf.us-east-2.rds.amazonaws.com" (18.218.251.218), port 5432 failed: Connection refused
	Is the server running on that host and accepting TCP/IP connections?
connection to server at "database-1.cfwk0mcqm9mf.us-east-2.rds.amazonaws.com" (18.218.251.218), port 5432 failed: Connection refused
	Is the server running on that host and accepting TCP/IP connections?
[2024-11-29T04:21:41.634+0000] {logging_mixin.py:190} INFO - Ingesting new data into cfdaprograms
[2024-11-29T04:22:23.773+0000] {logging_mixin.py:190} INFO - Error: connection to server at "database-1.cfwk0mcqm9mf.us-east-2.rds.amazonaws.com" (18.218.251.218), port 5432 failed: Connection refused
	Is the server running on that host and accepting TCP/IP connections?
connection to server at "database-1.cfwk0mcqm9mf.us-east-2.rds.amazonaws.com" (18.218.251.218), port 5432 failed: Connection refused
	Is the server running on that host and accepting TCP/IP connections?
[2024-11-29T04:22:24.078+0000] {logging_mixin.py:190} INFO - Checking for new data to ingest into recipients
[2024-11-29T04:23:06.202+0000] {logging_mixin.py:190} INFO - Error fetching existing data from recipients: connection to server at "database-1.cfwk0mcqm9mf.us-east-2.rds.amazonaws.com" (18.218.251.218), port 5432 failed: Connection refused
	Is the server running on that host and accepting TCP/IP connections?
connection to server at "database-1.cfwk0mcqm9mf.us-east-2.rds.amazonaws.com" (18.218.251.218), port 5432 failed: Connection refused
	Is the server running on that host and accepting TCP/IP connections?
[2024-11-29T04:23:06.204+0000] {logging_mixin.py:190} INFO - Ingesting new data into recipients
[2024-11-29T04:23:48.381+0000] {logging_mixin.py:190} INFO - Error: connection to server at "database-1.cfwk0mcqm9mf.us-east-2.rds.amazonaws.com" (18.218.251.218), port 5432 failed: Connection refused
	Is the server running on that host and accepting TCP/IP connections?
connection to server at "database-1.cfwk0mcqm9mf.us-east-2.rds.amazonaws.com" (18.218.251.218), port 5432 failed: Connection refused
	Is the server running on that host and accepting TCP/IP connections?
[2024-11-29T04:23:48.645+0000] {logging_mixin.py:190} INFO - Checking for new data to ingest into agencies
[2024-11-29T04:24:30.757+0000] {logging_mixin.py:190} INFO - Error fetching existing data from agencies: connection to server at "database-1.cfwk0mcqm9mf.us-east-2.rds.amazonaws.com" (18.218.251.218), port 5432 failed: Connection refused
	Is the server running on that host and accepting TCP/IP connections?
connection to server at "database-1.cfwk0mcqm9mf.us-east-2.rds.amazonaws.com" (18.218.251.218), port 5432 failed: Connection refused
	Is the server running on that host and accepting TCP/IP connections?
[2024-11-29T04:24:30.758+0000] {logging_mixin.py:190} INFO - Ingesting new data into agencies
[2024-11-29T04:25:12.913+0000] {logging_mixin.py:190} INFO - Error: connection to server at "database-1.cfwk0mcqm9mf.us-east-2.rds.amazonaws.com" (18.218.251.218), port 5432 failed: Connection refused
	Is the server running on that host and accepting TCP/IP connections?
connection to server at "database-1.cfwk0mcqm9mf.us-east-2.rds.amazonaws.com" (18.218.251.218), port 5432 failed: Connection refused
	Is the server running on that host and accepting TCP/IP connections?
[2024-11-29T04:25:13.108+0000] {logging_mixin.py:190} INFO - Checking for new data to ingest into subagency
[2024-11-29T04:25:55.247+0000] {logging_mixin.py:190} INFO - Error fetching existing data from subagency: connection to server at "database-1.cfwk0mcqm9mf.us-east-2.rds.amazonaws.com" (18.218.251.218), port 5432 failed: Connection refused
	Is the server running on that host and accepting TCP/IP connections?
connection to server at "database-1.cfwk0mcqm9mf.us-east-2.rds.amazonaws.com" (18.218.251.218), port 5432 failed: Connection refused
	Is the server running on that host and accepting TCP/IP connections?
[2024-11-29T04:25:55.248+0000] {logging_mixin.py:190} INFO - Ingesting new data into subagency
[2024-11-29T04:26:37.381+0000] {logging_mixin.py:190} INFO - Error: connection to server at "database-1.cfwk0mcqm9mf.us-east-2.rds.amazonaws.com" (18.218.251.218), port 5432 failed: Connection refused
	Is the server running on that host and accepting TCP/IP connections?
connection to server at "database-1.cfwk0mcqm9mf.us-east-2.rds.amazonaws.com" (18.218.251.218), port 5432 failed: Connection refused
	Is the server running on that host and accepting TCP/IP connections?
[2024-11-29T04:26:37.758+0000] {logging_mixin.py:190} INFO - Checking for new data to ingest into grants
[2024-11-29T04:27:19.920+0000] {logging_mixin.py:190} INFO - Error fetching existing data from grants: connection to server at "database-1.cfwk0mcqm9mf.us-east-2.rds.amazonaws.com" (18.218.251.218), port 5432 failed: Connection refused
	Is the server running on that host and accepting TCP/IP connections?
connection to server at "database-1.cfwk0mcqm9mf.us-east-2.rds.amazonaws.com" (18.218.251.218), port 5432 failed: Connection refused
	Is the server running on that host and accepting TCP/IP connections?
[2024-11-29T04:27:19.940+0000] {taskinstance.py:3311} ERROR - Task failed with exception
Traceback (most recent call last):
  File "/home/airflow/.local/lib/python3.12/site-packages/airflow/models/taskinstance.py", line 767, in _execute_task
    result = _execute_callable(context=context, **execute_callable_kwargs)
             ^^^^^^^^^^^^^^^^^^^^^^^^^^^^^^^^^^^^^^^^^^^^^^^^^^^^^^^^^^^^^
  File "/home/airflow/.local/lib/python3.12/site-packages/airflow/models/taskinstance.py", line 733, in _execute_callable
    return ExecutionCallableRunner(
           ^^^^^^^^^^^^^^^^^^^^^^^^
  File "/home/airflow/.local/lib/python3.12/site-packages/airflow/utils/operator_helpers.py", line 252, in run
    return self.func(*args, **kwargs)
           ^^^^^^^^^^^^^^^^^^^^^^^^^^
  File "/home/airflow/.local/lib/python3.12/site-packages/airflow/models/baseoperator.py", line 417, in wrapper
    return func(self, *args, **kwargs)
           ^^^^^^^^^^^^^^^^^^^^^^^^^^^
  File "/home/airflow/.local/lib/python3.12/site-packages/airflow/operators/python.py", line 238, in execute
    return_value = self.execute_callable()
                   ^^^^^^^^^^^^^^^^^^^^^^^
  File "/home/airflow/.local/lib/python3.12/site-packages/airflow/operators/python.py", line 256, in execute_callable
    return runner.run(*self.op_args, **self.op_kwargs)
           ^^^^^^^^^^^^^^^^^^^^^^^^^^^^^^^^^^^^^^^^^^^
  File "/home/airflow/.local/lib/python3.12/site-packages/airflow/utils/operator_helpers.py", line 252, in run
    return self.func(*args, **kwargs)
           ^^^^^^^^^^^^^^^^^^^^^^^^^^
  File "/opt/airflow/dags/data_ingestion/usa_spending_data_ingestion.py", line 115, in ingest_usa_spending_data
    new_data_df = check_and_filter_new_data(df, table)
                  ^^^^^^^^^^^^^^^^^^^^^^^^^^^^^^^^^^^^
  File "/opt/airflow/dags/data_ingestion/usa_spending_data_ingestion.py", line 55, in check_and_filter_new_data
    existing_data['start_date']= pd.to_datetime(existing_data["start_date"], errors="coerce").dt.strftime("%m-%d-%Y")
                                                ~~~~~~~~~~~~~^^^^^^^^^^^^^^
TypeError: 'NoneType' object is not subscriptable
[2024-11-29T04:27:20.026+0000] {taskinstance.py:1225} INFO - Marking task as FAILED. dag_id=ETL_usa_spending, task_id=ingest_usa_spending_data_task, run_id=scheduled__2024-11-28T00:00:00+00:00, execution_date=20241128T000000, start_date=20241129T041954, end_date=20241129T042720
[2024-11-29T04:27:20.064+0000] {taskinstance.py:340} INFO - ::group::Post task execution logs
[2024-11-29T04:27:20.065+0000] {standard_task_runner.py:124} ERROR - Failed to execute job 462 for task ingest_usa_spending_data_task ('NoneType' object is not subscriptable; 45357)
Traceback (most recent call last):
  File "/home/airflow/.local/lib/python3.12/site-packages/airflow/task/task_runner/standard_task_runner.py", line 117, in _start_by_fork
    ret = args.func(args, dag=self.dag)
          ^^^^^^^^^^^^^^^^^^^^^^^^^^^^^
  File "/home/airflow/.local/lib/python3.12/site-packages/airflow/cli/cli_config.py", line 49, in command
    return func(*args, **kwargs)
           ^^^^^^^^^^^^^^^^^^^^^
  File "/home/airflow/.local/lib/python3.12/site-packages/airflow/utils/cli.py", line 116, in wrapper
    return f(*args, **kwargs)
           ^^^^^^^^^^^^^^^^^^
  File "/home/airflow/.local/lib/python3.12/site-packages/airflow/cli/commands/task_command.py", line 483, in task_run
    task_return_code = _run_task_by_selected_method(args, _dag, ti)
                       ^^^^^^^^^^^^^^^^^^^^^^^^^^^^^^^^^^^^^^^^^^^^
  File "/home/airflow/.local/lib/python3.12/site-packages/airflow/cli/commands/task_command.py", line 256, in _run_task_by_selected_method
    return _run_raw_task(args, ti)
           ^^^^^^^^^^^^^^^^^^^^^^^
  File "/home/airflow/.local/lib/python3.12/site-packages/airflow/cli/commands/task_command.py", line 341, in _run_raw_task
    return ti._run_raw_task(
           ^^^^^^^^^^^^^^^^^
  File "/home/airflow/.local/lib/python3.12/site-packages/airflow/utils/session.py", line 97, in wrapper
    return func(*args, session=session, **kwargs)
           ^^^^^^^^^^^^^^^^^^^^^^^^^^^^^^^^^^^^^^
  File "/home/airflow/.local/lib/python3.12/site-packages/airflow/models/taskinstance.py", line 3005, in _run_raw_task
    return _run_raw_task(
           ^^^^^^^^^^^^^^
  File "/home/airflow/.local/lib/python3.12/site-packages/airflow/models/taskinstance.py", line 273, in _run_raw_task
    TaskInstance._execute_task_with_callbacks(
  File "/home/airflow/.local/lib/python3.12/site-packages/airflow/models/taskinstance.py", line 3159, in _execute_task_with_callbacks
    result = self._execute_task(context, task_orig)
             ^^^^^^^^^^^^^^^^^^^^^^^^^^^^^^^^^^^^^^
  File "/home/airflow/.local/lib/python3.12/site-packages/airflow/models/taskinstance.py", line 3183, in _execute_task
    return _execute_task(self, context, task_orig)
           ^^^^^^^^^^^^^^^^^^^^^^^^^^^^^^^^^^^^^^^
  File "/home/airflow/.local/lib/python3.12/site-packages/airflow/models/taskinstance.py", line 767, in _execute_task
    result = _execute_callable(context=context, **execute_callable_kwargs)
             ^^^^^^^^^^^^^^^^^^^^^^^^^^^^^^^^^^^^^^^^^^^^^^^^^^^^^^^^^^^^^
  File "/home/airflow/.local/lib/python3.12/site-packages/airflow/models/taskinstance.py", line 733, in _execute_callable
    return ExecutionCallableRunner(
           ^^^^^^^^^^^^^^^^^^^^^^^^
  File "/home/airflow/.local/lib/python3.12/site-packages/airflow/utils/operator_helpers.py", line 252, in run
    return self.func(*args, **kwargs)
           ^^^^^^^^^^^^^^^^^^^^^^^^^^
  File "/home/airflow/.local/lib/python3.12/site-packages/airflow/models/baseoperator.py", line 417, in wrapper
    return func(self, *args, **kwargs)
           ^^^^^^^^^^^^^^^^^^^^^^^^^^^
  File "/home/airflow/.local/lib/python3.12/site-packages/airflow/operators/python.py", line 238, in execute
    return_value = self.execute_callable()
                   ^^^^^^^^^^^^^^^^^^^^^^^
  File "/home/airflow/.local/lib/python3.12/site-packages/airflow/operators/python.py", line 256, in execute_callable
    return runner.run(*self.op_args, **self.op_kwargs)
           ^^^^^^^^^^^^^^^^^^^^^^^^^^^^^^^^^^^^^^^^^^^
  File "/home/airflow/.local/lib/python3.12/site-packages/airflow/utils/operator_helpers.py", line 252, in run
    return self.func(*args, **kwargs)
           ^^^^^^^^^^^^^^^^^^^^^^^^^^
  File "/opt/airflow/dags/data_ingestion/usa_spending_data_ingestion.py", line 115, in ingest_usa_spending_data
    new_data_df = check_and_filter_new_data(df, table)
                  ^^^^^^^^^^^^^^^^^^^^^^^^^^^^^^^^^^^^
  File "/opt/airflow/dags/data_ingestion/usa_spending_data_ingestion.py", line 55, in check_and_filter_new_data
    existing_data['start_date']= pd.to_datetime(existing_data["start_date"], errors="coerce").dt.strftime("%m-%d-%Y")
                                                ~~~~~~~~~~~~~^^^^^^^^^^^^^^
TypeError: 'NoneType' object is not subscriptable
[2024-11-29T04:27:20.109+0000] {local_task_job_runner.py:266} INFO - Task exited with return code 1
[2024-11-29T04:27:20.132+0000] {taskinstance.py:3895} INFO - 0 downstream tasks scheduled from follow-on schedule check
[2024-11-29T04:27:20.135+0000] {local_task_job_runner.py:245} INFO - ::endgroup::
