[2024-11-22T05:25:12.208+0000] {local_task_job_runner.py:123} INFO - ::group::Pre task execution logs
[2024-11-22T05:25:12.232+0000] {taskinstance.py:2613} INFO - Dependencies all met for dep_context=non-requeueable deps ti=<TaskInstance: ETL_usa_spending.process_usa_spending_data_task manual__2024-11-22T05:25:08.588526+00:00 [queued]>
[2024-11-22T05:25:12.244+0000] {taskinstance.py:2613} INFO - Dependencies all met for dep_context=requeueable deps ti=<TaskInstance: ETL_usa_spending.process_usa_spending_data_task manual__2024-11-22T05:25:08.588526+00:00 [queued]>
[2024-11-22T05:25:12.245+0000] {taskinstance.py:2866} INFO - Starting attempt 1 of 1
[2024-11-22T05:25:12.270+0000] {taskinstance.py:2889} INFO - Executing <Task(PythonOperator): process_usa_spending_data_task> on 2024-11-22 05:25:08.588526+00:00
[2024-11-22T05:25:12.283+0000] {logging_mixin.py:190} WARNING - /home/***/.local/lib/python3.12/site-packages/***/task/task_runner/standard_task_runner.py:70 DeprecationWarning: This process (pid=71190) is multi-threaded, use of fork() may lead to deadlocks in the child.
[2024-11-22T05:25:12.285+0000] {standard_task_runner.py:72} INFO - Started process 71198 to run task
[2024-11-22T05:25:12.283+0000] {standard_task_runner.py:104} INFO - Running: ['***', 'tasks', 'run', 'ETL_usa_spending', 'process_usa_spending_data_task', 'manual__2024-11-22T05:25:08.588526+00:00', '--job-id', '163', '--raw', '--subdir', 'DAGS_FOLDER/project_dag.py', '--cfg-path', '/tmp/tmpffkga2q2']
[2024-11-22T05:25:12.286+0000] {standard_task_runner.py:105} INFO - Job 163: Subtask process_usa_spending_data_task
[2024-11-22T05:25:12.352+0000] {task_command.py:467} INFO - Running <TaskInstance: ETL_usa_spending.process_usa_spending_data_task manual__2024-11-22T05:25:08.588526+00:00 [running]> on host 7da4b16cbed4
[2024-11-22T05:25:12.475+0000] {taskinstance.py:3132} INFO - Exporting env vars: AIRFLOW_CTX_DAG_OWNER='***' AIRFLOW_CTX_DAG_ID='ETL_usa_spending' AIRFLOW_CTX_TASK_ID='process_usa_spending_data_task' AIRFLOW_CTX_EXECUTION_DATE='2024-11-22T05:25:08.588526+00:00' AIRFLOW_CTX_TRY_NUMBER='1' AIRFLOW_CTX_DAG_RUN_ID='manual__2024-11-22T05:25:08.588526+00:00'
[2024-11-22T05:25:12.477+0000] {taskinstance.py:731} INFO - ::endgroup::
[2024-11-22T05:25:12.963+0000] {logging_mixin.py:190} INFO - Processing file: df_spending_by_award_11_17_2024.csv
[2024-11-22T05:25:13.510+0000] {logging_mixin.py:190} INFO - Processing file: federal_account_funding_df_2024-11-17.csv
[2024-11-22T05:25:14.034+0000] {logging_mixin.py:190} INFO - Processing file: other_variables_11_17_2024.csv
[2024-11-22T05:25:14.405+0000] {logging_mixin.py:190} INFO - Processing file: sub_award_df_2024-11-17.csv
[2024-11-22T05:25:14.729+0000] {logging_mixin.py:190} INFO - Processing file: transactions_df_2024-11-17.csv
[2024-11-22T05:25:16.905+0000] {taskinstance.py:3311} ERROR - Task failed with exception
Traceback (most recent call last):
  File "/home/airflow/.local/lib/python3.12/site-packages/pandas/core/indexes/base.py", line 3791, in get_loc
    return self._engine.get_loc(casted_key)
           ^^^^^^^^^^^^^^^^^^^^^^^^^^^^^^^^
  File "index.pyx", line 152, in pandas._libs.index.IndexEngine.get_loc
  File "index.pyx", line 181, in pandas._libs.index.IndexEngine.get_loc
  File "pandas/_libs/hashtable_class_helper.pxi", line 7080, in pandas._libs.hashtable.PyObjectHashTable.get_item
  File "pandas/_libs/hashtable_class_helper.pxi", line 7088, in pandas._libs.hashtable.PyObjectHashTable.get_item
KeyError: 'awarding_sub_agency_code'

The above exception was the direct cause of the following exception:

Traceback (most recent call last):
  File "/home/airflow/.local/lib/python3.12/site-packages/airflow/models/taskinstance.py", line 767, in _execute_task
    result = _execute_callable(context=context, **execute_callable_kwargs)
             ^^^^^^^^^^^^^^^^^^^^^^^^^^^^^^^^^^^^^^^^^^^^^^^^^^^^^^^^^^^^^
  File "/home/airflow/.local/lib/python3.12/site-packages/airflow/models/taskinstance.py", line 733, in _execute_callable
    return ExecutionCallableRunner(
           ^^^^^^^^^^^^^^^^^^^^^^^^
  File "/home/airflow/.local/lib/python3.12/site-packages/airflow/utils/operator_helpers.py", line 252, in run
    return self.func(*args, **kwargs)
           ^^^^^^^^^^^^^^^^^^^^^^^^^^
  File "/home/airflow/.local/lib/python3.12/site-packages/airflow/models/baseoperator.py", line 417, in wrapper
    return func(self, *args, **kwargs)
           ^^^^^^^^^^^^^^^^^^^^^^^^^^^
  File "/home/airflow/.local/lib/python3.12/site-packages/airflow/operators/python.py", line 238, in execute
    return_value = self.execute_callable()
                   ^^^^^^^^^^^^^^^^^^^^^^^
  File "/home/airflow/.local/lib/python3.12/site-packages/airflow/operators/python.py", line 256, in execute_callable
    return runner.run(*self.op_args, **self.op_kwargs)
           ^^^^^^^^^^^^^^^^^^^^^^^^^^^^^^^^^^^^^^^^^^^
  File "/home/airflow/.local/lib/python3.12/site-packages/airflow/utils/operator_helpers.py", line 252, in run
    return self.func(*args, **kwargs)
           ^^^^^^^^^^^^^^^^^^^^^^^^^^
  File "/opt/airflow/dags/data_extraction/usa_spending_extraction_script.py", line 448, in process_usa_spending_data
    federal_awards_df = get_federal_awards_data(awards_df, sub_agency_df)
                        ^^^^^^^^^^^^^^^^^^^^^^^^^^^^^^^^^^^^^^^^^^^^^^^^^
  File "/opt/airflow/dags/data_extraction/usa_spending_extraction_script.py", line 352, in get_federal_awards_data
    result["awarding_sub_agency_code"] = result["awarding_sub_agency_code"].astype(int)
                                         ~~~~~~^^^^^^^^^^^^^^^^^^^^^^^^^^^^
  File "/home/airflow/.local/lib/python3.12/site-packages/pandas/core/frame.py", line 3893, in __getitem__
    indexer = self.columns.get_loc(key)
              ^^^^^^^^^^^^^^^^^^^^^^^^^
  File "/home/airflow/.local/lib/python3.12/site-packages/pandas/core/indexes/base.py", line 3798, in get_loc
    raise KeyError(key) from err
KeyError: 'awarding_sub_agency_code'
[2024-11-22T05:25:16.934+0000] {taskinstance.py:1225} INFO - Marking task as FAILED. dag_id=ETL_usa_spending, task_id=process_usa_spending_data_task, run_id=manual__2024-11-22T05:25:08.588526+00:00, execution_date=20241122T052508, start_date=20241122T052512, end_date=20241122T052516
[2024-11-22T05:25:16.950+0000] {taskinstance.py:340} INFO - ::group::Post task execution logs
[2024-11-22T05:25:16.951+0000] {standard_task_runner.py:124} ERROR - Failed to execute job 163 for task process_usa_spending_data_task ('awarding_sub_agency_code'; 71198)
Traceback (most recent call last):
  File "/home/airflow/.local/lib/python3.12/site-packages/pandas/core/indexes/base.py", line 3791, in get_loc
    return self._engine.get_loc(casted_key)
           ^^^^^^^^^^^^^^^^^^^^^^^^^^^^^^^^
  File "index.pyx", line 152, in pandas._libs.index.IndexEngine.get_loc
  File "index.pyx", line 181, in pandas._libs.index.IndexEngine.get_loc
  File "pandas/_libs/hashtable_class_helper.pxi", line 7080, in pandas._libs.hashtable.PyObjectHashTable.get_item
  File "pandas/_libs/hashtable_class_helper.pxi", line 7088, in pandas._libs.hashtable.PyObjectHashTable.get_item
KeyError: 'awarding_sub_agency_code'

The above exception was the direct cause of the following exception:

Traceback (most recent call last):
  File "/home/airflow/.local/lib/python3.12/site-packages/airflow/task/task_runner/standard_task_runner.py", line 117, in _start_by_fork
    ret = args.func(args, dag=self.dag)
          ^^^^^^^^^^^^^^^^^^^^^^^^^^^^^
  File "/home/airflow/.local/lib/python3.12/site-packages/airflow/cli/cli_config.py", line 49, in command
    return func(*args, **kwargs)
           ^^^^^^^^^^^^^^^^^^^^^
  File "/home/airflow/.local/lib/python3.12/site-packages/airflow/utils/cli.py", line 116, in wrapper
    return f(*args, **kwargs)
           ^^^^^^^^^^^^^^^^^^
  File "/home/airflow/.local/lib/python3.12/site-packages/airflow/cli/commands/task_command.py", line 483, in task_run
    task_return_code = _run_task_by_selected_method(args, _dag, ti)
                       ^^^^^^^^^^^^^^^^^^^^^^^^^^^^^^^^^^^^^^^^^^^^
  File "/home/airflow/.local/lib/python3.12/site-packages/airflow/cli/commands/task_command.py", line 256, in _run_task_by_selected_method
    return _run_raw_task(args, ti)
           ^^^^^^^^^^^^^^^^^^^^^^^
  File "/home/airflow/.local/lib/python3.12/site-packages/airflow/cli/commands/task_command.py", line 341, in _run_raw_task
    return ti._run_raw_task(
           ^^^^^^^^^^^^^^^^^
  File "/home/airflow/.local/lib/python3.12/site-packages/airflow/utils/session.py", line 97, in wrapper
    return func(*args, session=session, **kwargs)
           ^^^^^^^^^^^^^^^^^^^^^^^^^^^^^^^^^^^^^^
  File "/home/airflow/.local/lib/python3.12/site-packages/airflow/models/taskinstance.py", line 3005, in _run_raw_task
    return _run_raw_task(
           ^^^^^^^^^^^^^^
  File "/home/airflow/.local/lib/python3.12/site-packages/airflow/models/taskinstance.py", line 273, in _run_raw_task
    TaskInstance._execute_task_with_callbacks(
  File "/home/airflow/.local/lib/python3.12/site-packages/airflow/models/taskinstance.py", line 3159, in _execute_task_with_callbacks
    result = self._execute_task(context, task_orig)
             ^^^^^^^^^^^^^^^^^^^^^^^^^^^^^^^^^^^^^^
  File "/home/airflow/.local/lib/python3.12/site-packages/airflow/models/taskinstance.py", line 3183, in _execute_task
    return _execute_task(self, context, task_orig)
           ^^^^^^^^^^^^^^^^^^^^^^^^^^^^^^^^^^^^^^^
  File "/home/airflow/.local/lib/python3.12/site-packages/airflow/models/taskinstance.py", line 767, in _execute_task
    result = _execute_callable(context=context, **execute_callable_kwargs)
             ^^^^^^^^^^^^^^^^^^^^^^^^^^^^^^^^^^^^^^^^^^^^^^^^^^^^^^^^^^^^^
  File "/home/airflow/.local/lib/python3.12/site-packages/airflow/models/taskinstance.py", line 733, in _execute_callable
    return ExecutionCallableRunner(
           ^^^^^^^^^^^^^^^^^^^^^^^^
  File "/home/airflow/.local/lib/python3.12/site-packages/airflow/utils/operator_helpers.py", line 252, in run
    return self.func(*args, **kwargs)
           ^^^^^^^^^^^^^^^^^^^^^^^^^^
  File "/home/airflow/.local/lib/python3.12/site-packages/airflow/models/baseoperator.py", line 417, in wrapper
    return func(self, *args, **kwargs)
           ^^^^^^^^^^^^^^^^^^^^^^^^^^^
  File "/home/airflow/.local/lib/python3.12/site-packages/airflow/operators/python.py", line 238, in execute
    return_value = self.execute_callable()
                   ^^^^^^^^^^^^^^^^^^^^^^^
  File "/home/airflow/.local/lib/python3.12/site-packages/airflow/operators/python.py", line 256, in execute_callable
    return runner.run(*self.op_args, **self.op_kwargs)
           ^^^^^^^^^^^^^^^^^^^^^^^^^^^^^^^^^^^^^^^^^^^
  File "/home/airflow/.local/lib/python3.12/site-packages/airflow/utils/operator_helpers.py", line 252, in run
    return self.func(*args, **kwargs)
           ^^^^^^^^^^^^^^^^^^^^^^^^^^
  File "/opt/airflow/dags/data_extraction/usa_spending_extraction_script.py", line 448, in process_usa_spending_data
    federal_awards_df = get_federal_awards_data(awards_df, sub_agency_df)
                        ^^^^^^^^^^^^^^^^^^^^^^^^^^^^^^^^^^^^^^^^^^^^^^^^^
  File "/opt/airflow/dags/data_extraction/usa_spending_extraction_script.py", line 352, in get_federal_awards_data
    result["awarding_sub_agency_code"] = result["awarding_sub_agency_code"].astype(int)
                                         ~~~~~~^^^^^^^^^^^^^^^^^^^^^^^^^^^^
  File "/home/airflow/.local/lib/python3.12/site-packages/pandas/core/frame.py", line 3893, in __getitem__
    indexer = self.columns.get_loc(key)
              ^^^^^^^^^^^^^^^^^^^^^^^^^
  File "/home/airflow/.local/lib/python3.12/site-packages/pandas/core/indexes/base.py", line 3798, in get_loc
    raise KeyError(key) from err
KeyError: 'awarding_sub_agency_code'
[2024-11-22T05:25:17.000+0000] {local_task_job_runner.py:266} INFO - Task exited with return code 1
[2024-11-22T05:25:17.017+0000] {taskinstance.py:3895} INFO - 0 downstream tasks scheduled from follow-on schedule check
[2024-11-22T05:25:17.020+0000] {local_task_job_runner.py:245} INFO - ::endgroup::
