[2024-11-11T07:06:22.887+0000] {local_task_job_runner.py:123} INFO - ::group::Pre task execution logs
[2024-11-11T07:06:22.986+0000] {taskinstance.py:2613} INFO - Dependencies all met for dep_context=non-requeueable deps ti=<TaskInstance: fetch_financial_reports.fetch_cdbg_dr_reports_task scheduled__2024-11-10T00:00:00+00:00 [queued]>
[2024-11-11T07:06:23.018+0000] {taskinstance.py:2613} INFO - Dependencies all met for dep_context=requeueable deps ti=<TaskInstance: fetch_financial_reports.fetch_cdbg_dr_reports_task scheduled__2024-11-10T00:00:00+00:00 [queued]>
[2024-11-11T07:06:23.038+0000] {taskinstance.py:2866} INFO - Starting attempt 2 of 2
[2024-11-11T07:06:23.120+0000] {taskinstance.py:2889} INFO - Executing <Task(PythonOperator): fetch_cdbg_dr_reports_task> on 2024-11-10 00:00:00+00:00
[2024-11-11T07:06:23.142+0000] {standard_task_runner.py:104} INFO - Running: ['***', 'tasks', 'run', 'fetch_financial_reports', 'fetch_cdbg_dr_reports_task', 'scheduled__2024-11-10T00:00:00+00:00', '--job-id', '7', '--raw', '--subdir', 'DAGS_FOLDER/web_scraper.py', '--cfg-path', '/tmp/tmpixc9evb2']
[2024-11-11T07:06:23.165+0000] {standard_task_runner.py:105} INFO - Job 7: Subtask fetch_cdbg_dr_reports_task
[2024-11-11T07:06:23.166+0000] {logging_mixin.py:190} WARNING - /home/***/.local/lib/python3.12/site-packages/***/task/task_runner/standard_task_runner.py:70 DeprecationWarning: This process (pid=362) is multi-threaded, use of fork() may lead to deadlocks in the child.
[2024-11-11T07:06:23.171+0000] {standard_task_runner.py:72} INFO - Started process 363 to run task
[2024-11-11T07:06:23.486+0000] {task_command.py:467} INFO - Running <TaskInstance: fetch_financial_reports.fetch_cdbg_dr_reports_task scheduled__2024-11-10T00:00:00+00:00 [running]> on host d6783a5c6023
[2024-11-11T07:06:23.770+0000] {taskinstance.py:3132} INFO - Exporting env vars: AIRFLOW_CTX_DAG_OWNER='***' AIRFLOW_CTX_DAG_ID='fetch_financial_reports' AIRFLOW_CTX_TASK_ID='fetch_cdbg_dr_reports_task' AIRFLOW_CTX_EXECUTION_DATE='2024-11-10T00:00:00+00:00' AIRFLOW_CTX_TRY_NUMBER='2' AIRFLOW_CTX_DAG_RUN_ID='scheduled__2024-11-10T00:00:00+00:00'
[2024-11-11T07:06:23.774+0000] {taskinstance.py:731} INFO - ::endgroup::
[2024-11-11T07:06:25.568+0000] {taskinstance.py:3311} ERROR - Task failed with exception
Traceback (most recent call last):
  File "/home/airflow/.local/lib/python3.12/site-packages/airflow/models/taskinstance.py", line 767, in _execute_task
    result = _execute_callable(context=context, **execute_callable_kwargs)
             ^^^^^^^^^^^^^^^^^^^^^^^^^^^^^^^^^^^^^^^^^^^^^^^^^^^^^^^^^^^^^
  File "/home/airflow/.local/lib/python3.12/site-packages/airflow/models/taskinstance.py", line 733, in _execute_callable
    return ExecutionCallableRunner(
           ^^^^^^^^^^^^^^^^^^^^^^^^
  File "/home/airflow/.local/lib/python3.12/site-packages/airflow/utils/operator_helpers.py", line 252, in run
    return self.func(*args, **kwargs)
           ^^^^^^^^^^^^^^^^^^^^^^^^^^
  File "/home/airflow/.local/lib/python3.12/site-packages/airflow/models/baseoperator.py", line 417, in wrapper
    return func(self, *args, **kwargs)
           ^^^^^^^^^^^^^^^^^^^^^^^^^^^
  File "/home/airflow/.local/lib/python3.12/site-packages/airflow/operators/python.py", line 238, in execute
    return_value = self.execute_callable()
                   ^^^^^^^^^^^^^^^^^^^^^^^
  File "/home/airflow/.local/lib/python3.12/site-packages/airflow/operators/python.py", line 256, in execute_callable
    return runner.run(*self.op_args, **self.op_kwargs)
           ^^^^^^^^^^^^^^^^^^^^^^^^^^^^^^^^^^^^^^^^^^^
  File "/home/airflow/.local/lib/python3.12/site-packages/airflow/utils/operator_helpers.py", line 252, in run
    return self.func(*args, **kwargs)
           ^^^^^^^^^^^^^^^^^^^^^^^^^^
  File "/opt/airflow/dags/web_scraper.py", line 65, in scrape_and_upload_reports
    fetch_cdbg_dr_reports(REPORTS_URL, target_file_name, bucket_name)
  File "/opt/airflow/dags/web_scraper.py", line 30, in fetch_cdbg_dr_reports
    existing_files = s3_client.list_objects_v2(Bucket=bucket_name, Prefix=s3_key)
                     ^^^^^^^^^^^^^^^^^^^^^^^^^^^^^^^^^^^^^^^^^^^^^^^^^^^^^^^^^^^^
  File "/home/airflow/.local/lib/python3.12/site-packages/botocore/client.py", line 569, in _api_call
    return self._make_api_call(operation_name, kwargs)
           ^^^^^^^^^^^^^^^^^^^^^^^^^^^^^^^^^^^^^^^^^^^
  File "/home/airflow/.local/lib/python3.12/site-packages/botocore/client.py", line 1023, in _make_api_call
    raise error_class(parsed_response, operation_name)
botocore.exceptions.ClientError: An error occurred (AccessDenied) when calling the ListObjectsV2 operation: Access Denied
[2024-11-11T07:06:25.612+0000] {taskinstance.py:1225} INFO - Marking task as FAILED. dag_id=fetch_financial_reports, task_id=fetch_cdbg_dr_reports_task, run_id=scheduled__2024-11-10T00:00:00+00:00, execution_date=20241110T000000, start_date=20241111T070622, end_date=20241111T070625
[2024-11-11T07:06:25.661+0000] {taskinstance.py:340} INFO - ::group::Post task execution logs
[2024-11-11T07:06:25.665+0000] {standard_task_runner.py:124} ERROR - Failed to execute job 7 for task fetch_cdbg_dr_reports_task (An error occurred (AccessDenied) when calling the ListObjectsV2 operation: Access Denied; 363)
Traceback (most recent call last):
  File "/home/airflow/.local/lib/python3.12/site-packages/airflow/task/task_runner/standard_task_runner.py", line 117, in _start_by_fork
    ret = args.func(args, dag=self.dag)
          ^^^^^^^^^^^^^^^^^^^^^^^^^^^^^
  File "/home/airflow/.local/lib/python3.12/site-packages/airflow/cli/cli_config.py", line 49, in command
    return func(*args, **kwargs)
           ^^^^^^^^^^^^^^^^^^^^^
  File "/home/airflow/.local/lib/python3.12/site-packages/airflow/utils/cli.py", line 116, in wrapper
    return f(*args, **kwargs)
           ^^^^^^^^^^^^^^^^^^
  File "/home/airflow/.local/lib/python3.12/site-packages/airflow/cli/commands/task_command.py", line 483, in task_run
    task_return_code = _run_task_by_selected_method(args, _dag, ti)
                       ^^^^^^^^^^^^^^^^^^^^^^^^^^^^^^^^^^^^^^^^^^^^
  File "/home/airflow/.local/lib/python3.12/site-packages/airflow/cli/commands/task_command.py", line 256, in _run_task_by_selected_method
    return _run_raw_task(args, ti)
           ^^^^^^^^^^^^^^^^^^^^^^^
  File "/home/airflow/.local/lib/python3.12/site-packages/airflow/cli/commands/task_command.py", line 341, in _run_raw_task
    return ti._run_raw_task(
           ^^^^^^^^^^^^^^^^^
  File "/home/airflow/.local/lib/python3.12/site-packages/airflow/utils/session.py", line 97, in wrapper
    return func(*args, session=session, **kwargs)
           ^^^^^^^^^^^^^^^^^^^^^^^^^^^^^^^^^^^^^^
  File "/home/airflow/.local/lib/python3.12/site-packages/airflow/models/taskinstance.py", line 3005, in _run_raw_task
    return _run_raw_task(
           ^^^^^^^^^^^^^^
  File "/home/airflow/.local/lib/python3.12/site-packages/airflow/models/taskinstance.py", line 273, in _run_raw_task
    TaskInstance._execute_task_with_callbacks(
  File "/home/airflow/.local/lib/python3.12/site-packages/airflow/models/taskinstance.py", line 3159, in _execute_task_with_callbacks
    result = self._execute_task(context, task_orig)
             ^^^^^^^^^^^^^^^^^^^^^^^^^^^^^^^^^^^^^^
  File "/home/airflow/.local/lib/python3.12/site-packages/airflow/models/taskinstance.py", line 3183, in _execute_task
    return _execute_task(self, context, task_orig)
           ^^^^^^^^^^^^^^^^^^^^^^^^^^^^^^^^^^^^^^^
  File "/home/airflow/.local/lib/python3.12/site-packages/airflow/models/taskinstance.py", line 767, in _execute_task
    result = _execute_callable(context=context, **execute_callable_kwargs)
             ^^^^^^^^^^^^^^^^^^^^^^^^^^^^^^^^^^^^^^^^^^^^^^^^^^^^^^^^^^^^^
  File "/home/airflow/.local/lib/python3.12/site-packages/airflow/models/taskinstance.py", line 733, in _execute_callable
    return ExecutionCallableRunner(
           ^^^^^^^^^^^^^^^^^^^^^^^^
  File "/home/airflow/.local/lib/python3.12/site-packages/airflow/utils/operator_helpers.py", line 252, in run
    return self.func(*args, **kwargs)
           ^^^^^^^^^^^^^^^^^^^^^^^^^^
  File "/home/airflow/.local/lib/python3.12/site-packages/airflow/models/baseoperator.py", line 417, in wrapper
    return func(self, *args, **kwargs)
           ^^^^^^^^^^^^^^^^^^^^^^^^^^^
  File "/home/airflow/.local/lib/python3.12/site-packages/airflow/operators/python.py", line 238, in execute
    return_value = self.execute_callable()
                   ^^^^^^^^^^^^^^^^^^^^^^^
  File "/home/airflow/.local/lib/python3.12/site-packages/airflow/operators/python.py", line 256, in execute_callable
    return runner.run(*self.op_args, **self.op_kwargs)
           ^^^^^^^^^^^^^^^^^^^^^^^^^^^^^^^^^^^^^^^^^^^
  File "/home/airflow/.local/lib/python3.12/site-packages/airflow/utils/operator_helpers.py", line 252, in run
    return self.func(*args, **kwargs)
           ^^^^^^^^^^^^^^^^^^^^^^^^^^
  File "/opt/airflow/dags/web_scraper.py", line 65, in scrape_and_upload_reports
    fetch_cdbg_dr_reports(REPORTS_URL, target_file_name, bucket_name)
  File "/opt/airflow/dags/web_scraper.py", line 30, in fetch_cdbg_dr_reports
    existing_files = s3_client.list_objects_v2(Bucket=bucket_name, Prefix=s3_key)
                     ^^^^^^^^^^^^^^^^^^^^^^^^^^^^^^^^^^^^^^^^^^^^^^^^^^^^^^^^^^^^
  File "/home/airflow/.local/lib/python3.12/site-packages/botocore/client.py", line 569, in _api_call
    return self._make_api_call(operation_name, kwargs)
           ^^^^^^^^^^^^^^^^^^^^^^^^^^^^^^^^^^^^^^^^^^^
  File "/home/airflow/.local/lib/python3.12/site-packages/botocore/client.py", line 1023, in _make_api_call
    raise error_class(parsed_response, operation_name)
botocore.exceptions.ClientError: An error occurred (AccessDenied) when calling the ListObjectsV2 operation: Access Denied
[2024-11-11T07:06:25.721+0000] {local_task_job_runner.py:266} INFO - Task exited with return code 1
[2024-11-11T07:06:25.793+0000] {taskinstance.py:3895} INFO - 0 downstream tasks scheduled from follow-on schedule check
[2024-11-11T07:06:25.805+0000] {local_task_job_runner.py:245} INFO - ::endgroup::
