[2024-11-25T07:21:02.278+0000] {local_task_job_runner.py:123} INFO - ::group::Pre task execution logs
[2024-11-25T07:21:02.301+0000] {taskinstance.py:2613} INFO - Dependencies all met for dep_context=non-requeueable deps ti=<TaskInstance: ETL_history_reports.process_history_reports_task manual__2024-11-25T07:20:53.906484+00:00 [queued]>
[2024-11-25T07:21:02.314+0000] {taskinstance.py:2613} INFO - Dependencies all met for dep_context=requeueable deps ti=<TaskInstance: ETL_history_reports.process_history_reports_task manual__2024-11-25T07:20:53.906484+00:00 [queued]>
[2024-11-25T07:21:02.315+0000] {taskinstance.py:2866} INFO - Starting attempt 1 of 1
[2024-11-25T07:21:02.336+0000] {taskinstance.py:2889} INFO - Executing <Task(PythonOperator): process_history_reports_task> on 2024-11-25 07:20:53.906484+00:00
[2024-11-25T07:21:02.346+0000] {logging_mixin.py:190} WARNING - /home/***/.local/lib/python3.12/site-packages/***/task/task_runner/standard_task_runner.py:70 DeprecationWarning: This process (pid=834) is multi-threaded, use of fork() may lead to deadlocks in the child.
[2024-11-25T07:21:02.347+0000] {standard_task_runner.py:72} INFO - Started process 836 to run task
[2024-11-25T07:21:02.345+0000] {standard_task_runner.py:104} INFO - Running: ['***', 'tasks', 'run', 'ETL_history_reports', 'process_history_reports_task', 'manual__2024-11-25T07:20:53.906484+00:00', '--job-id', '270', '--raw', '--subdir', 'DAGS_FOLDER/project_dag.py', '--cfg-path', '/tmp/tmphfh2wn9s']
[2024-11-25T07:21:02.348+0000] {standard_task_runner.py:105} INFO - Job 270: Subtask process_history_reports_task
[2024-11-25T07:21:02.402+0000] {task_command.py:467} INFO - Running <TaskInstance: ETL_history_reports.process_history_reports_task manual__2024-11-25T07:20:53.906484+00:00 [running]> on host 6a246d8d590f
[2024-11-25T07:21:02.744+0000] {taskinstance.py:3132} INFO - Exporting env vars: AIRFLOW_CTX_DAG_OWNER='***' AIRFLOW_CTX_DAG_ID='ETL_history_reports' AIRFLOW_CTX_TASK_ID='process_history_reports_task' AIRFLOW_CTX_EXECUTION_DATE='2024-11-25T07:20:53.906484+00:00' AIRFLOW_CTX_TRY_NUMBER='1' AIRFLOW_CTX_DAG_RUN_ID='manual__2024-11-25T07:20:53.906484+00:00'
[2024-11-25T07:21:02.745+0000] {taskinstance.py:731} INFO - ::endgroup::
[2024-11-25T07:21:05.415+0000] {taskinstance.py:3311} ERROR - Task failed with exception
Traceback (most recent call last):
  File "/home/airflow/.local/lib/python3.12/site-packages/airflow/models/taskinstance.py", line 767, in _execute_task
    result = _execute_callable(context=context, **execute_callable_kwargs)
             ^^^^^^^^^^^^^^^^^^^^^^^^^^^^^^^^^^^^^^^^^^^^^^^^^^^^^^^^^^^^^
  File "/home/airflow/.local/lib/python3.12/site-packages/airflow/models/taskinstance.py", line 733, in _execute_callable
    return ExecutionCallableRunner(
           ^^^^^^^^^^^^^^^^^^^^^^^^
  File "/home/airflow/.local/lib/python3.12/site-packages/airflow/utils/operator_helpers.py", line 252, in run
    return self.func(*args, **kwargs)
           ^^^^^^^^^^^^^^^^^^^^^^^^^^
  File "/home/airflow/.local/lib/python3.12/site-packages/airflow/models/baseoperator.py", line 417, in wrapper
    return func(self, *args, **kwargs)
           ^^^^^^^^^^^^^^^^^^^^^^^^^^^
  File "/home/airflow/.local/lib/python3.12/site-packages/airflow/operators/python.py", line 238, in execute
    return_value = self.execute_callable()
                   ^^^^^^^^^^^^^^^^^^^^^^^
  File "/home/airflow/.local/lib/python3.12/site-packages/airflow/operators/python.py", line 256, in execute_callable
    return runner.run(*self.op_args, **self.op_kwargs)
           ^^^^^^^^^^^^^^^^^^^^^^^^^^^^^^^^^^^^^^^^^^^
  File "/home/airflow/.local/lib/python3.12/site-packages/airflow/utils/operator_helpers.py", line 252, in run
    return self.func(*args, **kwargs)
           ^^^^^^^^^^^^^^^^^^^^^^^^^^
  File "/opt/airflow/dags/data_processing/history_reports_processing_script.py", line 299, in process_history_reports
    disaster_df,grantee_df,grant_df,publiclaw_df,disaster_publiclaw_df = convert_3_tables_to_5(grant_history,disaster_events,public_law_table)
                                                                         ^^^^^^^^^^^^^^^^^^^^^^^^^^^^^^^^^^^^^^^^^^^^^^^^^^^^^^^^^^^^^^^^^^^^^
  File "/opt/airflow/dags/data_processing/history_reports_processing_script.py", line 233, in convert_3_tables_to_5
    public_law_table['pl_date'] = public_law_table['pl_date'].apply(transform_date_column)
                                  ^^^^^^^^^^^^^^^^^^^^^^^^^^^^^^^^^^^^^^^^^^^^^^^^^^^^^^^^
  File "/home/airflow/.local/lib/python3.12/site-packages/pandas/core/series.py", line 4764, in apply
    ).apply()
      ^^^^^^^
  File "/home/airflow/.local/lib/python3.12/site-packages/pandas/core/apply.py", line 1209, in apply
    return self.apply_standard()
           ^^^^^^^^^^^^^^^^^^^^^
  File "/home/airflow/.local/lib/python3.12/site-packages/pandas/core/apply.py", line 1289, in apply_standard
    mapped = obj._map_values(
             ^^^^^^^^^^^^^^^^
  File "/home/airflow/.local/lib/python3.12/site-packages/pandas/core/base.py", line 921, in _map_values
    return algorithms.map_array(arr, mapper, na_action=na_action, convert=convert)
           ^^^^^^^^^^^^^^^^^^^^^^^^^^^^^^^^^^^^^^^^^^^^^^^^^^^^^^^^^^^^^^^^^^^^^^^
  File "/home/airflow/.local/lib/python3.12/site-packages/pandas/core/algorithms.py", line 1814, in map_array
    return lib.map_infer(values, mapper, convert=convert)
           ^^^^^^^^^^^^^^^^^^^^^^^^^^^^^^^^^^^^^^^^^^^^^^
  File "lib.pyx", line 2926, in pandas._libs.lib.map_infer
  File "/opt/airflow/dags/helpers/date_extractor.py", line 84, in transform_date_column
    standard_date = pd.to_datetime(date_str, errors='coerce').strftime('%Y-%m-%d')
                    ^^^^^^^^^^^^^^^^^^^^^^^^^^^^^^^^^^^^^^^^^^^^^^^^^^^^^^^^^^^^^^
  File "nattype.pyx", line 58, in pandas._libs.tslibs.nattype._make_error_func.f
ValueError: NaTType does not support strftime
[2024-11-25T07:21:05.444+0000] {taskinstance.py:1225} INFO - Marking task as FAILED. dag_id=ETL_history_reports, task_id=process_history_reports_task, run_id=manual__2024-11-25T07:20:53.906484+00:00, execution_date=20241125T072053, start_date=20241125T072102, end_date=20241125T072105
[2024-11-25T07:21:05.459+0000] {taskinstance.py:340} INFO - ::group::Post task execution logs
[2024-11-25T07:21:05.460+0000] {standard_task_runner.py:124} ERROR - Failed to execute job 270 for task process_history_reports_task (NaTType does not support strftime; 836)
Traceback (most recent call last):
  File "/home/airflow/.local/lib/python3.12/site-packages/airflow/task/task_runner/standard_task_runner.py", line 117, in _start_by_fork
    ret = args.func(args, dag=self.dag)
          ^^^^^^^^^^^^^^^^^^^^^^^^^^^^^
  File "/home/airflow/.local/lib/python3.12/site-packages/airflow/cli/cli_config.py", line 49, in command
    return func(*args, **kwargs)
           ^^^^^^^^^^^^^^^^^^^^^
  File "/home/airflow/.local/lib/python3.12/site-packages/airflow/utils/cli.py", line 116, in wrapper
    return f(*args, **kwargs)
           ^^^^^^^^^^^^^^^^^^
  File "/home/airflow/.local/lib/python3.12/site-packages/airflow/cli/commands/task_command.py", line 483, in task_run
    task_return_code = _run_task_by_selected_method(args, _dag, ti)
                       ^^^^^^^^^^^^^^^^^^^^^^^^^^^^^^^^^^^^^^^^^^^^
  File "/home/airflow/.local/lib/python3.12/site-packages/airflow/cli/commands/task_command.py", line 256, in _run_task_by_selected_method
    return _run_raw_task(args, ti)
           ^^^^^^^^^^^^^^^^^^^^^^^
  File "/home/airflow/.local/lib/python3.12/site-packages/airflow/cli/commands/task_command.py", line 341, in _run_raw_task
    return ti._run_raw_task(
           ^^^^^^^^^^^^^^^^^
  File "/home/airflow/.local/lib/python3.12/site-packages/airflow/utils/session.py", line 97, in wrapper
    return func(*args, session=session, **kwargs)
           ^^^^^^^^^^^^^^^^^^^^^^^^^^^^^^^^^^^^^^
  File "/home/airflow/.local/lib/python3.12/site-packages/airflow/models/taskinstance.py", line 3005, in _run_raw_task
    return _run_raw_task(
           ^^^^^^^^^^^^^^
  File "/home/airflow/.local/lib/python3.12/site-packages/airflow/models/taskinstance.py", line 273, in _run_raw_task
    TaskInstance._execute_task_with_callbacks(
  File "/home/airflow/.local/lib/python3.12/site-packages/airflow/models/taskinstance.py", line 3159, in _execute_task_with_callbacks
    result = self._execute_task(context, task_orig)
             ^^^^^^^^^^^^^^^^^^^^^^^^^^^^^^^^^^^^^^
  File "/home/airflow/.local/lib/python3.12/site-packages/airflow/models/taskinstance.py", line 3183, in _execute_task
    return _execute_task(self, context, task_orig)
           ^^^^^^^^^^^^^^^^^^^^^^^^^^^^^^^^^^^^^^^
  File "/home/airflow/.local/lib/python3.12/site-packages/airflow/models/taskinstance.py", line 767, in _execute_task
    result = _execute_callable(context=context, **execute_callable_kwargs)
             ^^^^^^^^^^^^^^^^^^^^^^^^^^^^^^^^^^^^^^^^^^^^^^^^^^^^^^^^^^^^^
  File "/home/airflow/.local/lib/python3.12/site-packages/airflow/models/taskinstance.py", line 733, in _execute_callable
    return ExecutionCallableRunner(
           ^^^^^^^^^^^^^^^^^^^^^^^^
  File "/home/airflow/.local/lib/python3.12/site-packages/airflow/utils/operator_helpers.py", line 252, in run
    return self.func(*args, **kwargs)
           ^^^^^^^^^^^^^^^^^^^^^^^^^^
  File "/home/airflow/.local/lib/python3.12/site-packages/airflow/models/baseoperator.py", line 417, in wrapper
    return func(self, *args, **kwargs)
           ^^^^^^^^^^^^^^^^^^^^^^^^^^^
  File "/home/airflow/.local/lib/python3.12/site-packages/airflow/operators/python.py", line 238, in execute
    return_value = self.execute_callable()
                   ^^^^^^^^^^^^^^^^^^^^^^^
  File "/home/airflow/.local/lib/python3.12/site-packages/airflow/operators/python.py", line 256, in execute_callable
    return runner.run(*self.op_args, **self.op_kwargs)
           ^^^^^^^^^^^^^^^^^^^^^^^^^^^^^^^^^^^^^^^^^^^
  File "/home/airflow/.local/lib/python3.12/site-packages/airflow/utils/operator_helpers.py", line 252, in run
    return self.func(*args, **kwargs)
           ^^^^^^^^^^^^^^^^^^^^^^^^^^
  File "/opt/airflow/dags/data_processing/history_reports_processing_script.py", line 299, in process_history_reports
    disaster_df,grantee_df,grant_df,publiclaw_df,disaster_publiclaw_df = convert_3_tables_to_5(grant_history,disaster_events,public_law_table)
                                                                         ^^^^^^^^^^^^^^^^^^^^^^^^^^^^^^^^^^^^^^^^^^^^^^^^^^^^^^^^^^^^^^^^^^^^^
  File "/opt/airflow/dags/data_processing/history_reports_processing_script.py", line 233, in convert_3_tables_to_5
    public_law_table['pl_date'] = public_law_table['pl_date'].apply(transform_date_column)
                                  ^^^^^^^^^^^^^^^^^^^^^^^^^^^^^^^^^^^^^^^^^^^^^^^^^^^^^^^^
  File "/home/airflow/.local/lib/python3.12/site-packages/pandas/core/series.py", line 4764, in apply
    ).apply()
      ^^^^^^^
  File "/home/airflow/.local/lib/python3.12/site-packages/pandas/core/apply.py", line 1209, in apply
    return self.apply_standard()
           ^^^^^^^^^^^^^^^^^^^^^
  File "/home/airflow/.local/lib/python3.12/site-packages/pandas/core/apply.py", line 1289, in apply_standard
    mapped = obj._map_values(
             ^^^^^^^^^^^^^^^^
  File "/home/airflow/.local/lib/python3.12/site-packages/pandas/core/base.py", line 921, in _map_values
    return algorithms.map_array(arr, mapper, na_action=na_action, convert=convert)
           ^^^^^^^^^^^^^^^^^^^^^^^^^^^^^^^^^^^^^^^^^^^^^^^^^^^^^^^^^^^^^^^^^^^^^^^
  File "/home/airflow/.local/lib/python3.12/site-packages/pandas/core/algorithms.py", line 1814, in map_array
    return lib.map_infer(values, mapper, convert=convert)
           ^^^^^^^^^^^^^^^^^^^^^^^^^^^^^^^^^^^^^^^^^^^^^^
  File "lib.pyx", line 2926, in pandas._libs.lib.map_infer
  File "/opt/airflow/dags/helpers/date_extractor.py", line 84, in transform_date_column
    standard_date = pd.to_datetime(date_str, errors='coerce').strftime('%Y-%m-%d')
                    ^^^^^^^^^^^^^^^^^^^^^^^^^^^^^^^^^^^^^^^^^^^^^^^^^^^^^^^^^^^^^^
  File "nattype.pyx", line 58, in pandas._libs.tslibs.nattype._make_error_func.f
ValueError: NaTType does not support strftime
[2024-11-25T07:21:05.494+0000] {local_task_job_runner.py:266} INFO - Task exited with return code 1
[2024-11-25T07:21:05.517+0000] {taskinstance.py:3895} INFO - 0 downstream tasks scheduled from follow-on schedule check
[2024-11-25T07:21:05.521+0000] {local_task_job_runner.py:245} INFO - ::endgroup::
