[2024-11-26T02:28:54.847+0000] {local_task_job_runner.py:123} INFO - ::group::Pre task execution logs
[2024-11-26T02:28:54.866+0000] {taskinstance.py:2613} INFO - Dependencies all met for dep_context=non-requeueable deps ti=<TaskInstance: ETL_quarterly_performance_reports.ingest_performance_reports_task manual__2024-11-26T02:28:49.028749+00:00 [queued]>
[2024-11-26T02:28:54.876+0000] {taskinstance.py:2613} INFO - Dependencies all met for dep_context=requeueable deps ti=<TaskInstance: ETL_quarterly_performance_reports.ingest_performance_reports_task manual__2024-11-26T02:28:49.028749+00:00 [queued]>
[2024-11-26T02:28:54.877+0000] {taskinstance.py:2866} INFO - Starting attempt 1 of 1
[2024-11-26T02:28:54.893+0000] {taskinstance.py:2889} INFO - Executing <Task(PythonOperator): ingest_performance_reports_task> on 2024-11-26 02:28:49.028749+00:00
[2024-11-26T02:28:54.902+0000] {standard_task_runner.py:104} INFO - Running: ['***', 'tasks', 'run', 'ETL_quarterly_performance_reports', 'ingest_performance_reports_task', 'manual__2024-11-26T02:28:49.028749+00:00', '--job-id', '327', '--raw', '--subdir', 'DAGS_FOLDER/project_dag.py', '--cfg-path', '/tmp/tmpnntk9k45']
[2024-11-26T02:28:54.903+0000] {logging_mixin.py:190} WARNING - /home/***/.local/lib/python3.12/site-packages/***/task/task_runner/standard_task_runner.py:70 DeprecationWarning: This process (pid=8296) is multi-threaded, use of fork() may lead to deadlocks in the child.
[2024-11-26T02:28:54.905+0000] {standard_task_runner.py:105} INFO - Job 327: Subtask ingest_performance_reports_task
[2024-11-26T02:28:54.905+0000] {standard_task_runner.py:72} INFO - Started process 8298 to run task
[2024-11-26T02:28:54.960+0000] {task_command.py:467} INFO - Running <TaskInstance: ETL_quarterly_performance_reports.ingest_performance_reports_task manual__2024-11-26T02:28:49.028749+00:00 [running]> on host 6a246d8d590f
[2024-11-26T02:28:55.265+0000] {taskinstance.py:3132} INFO - Exporting env vars: AIRFLOW_CTX_DAG_OWNER='***' AIRFLOW_CTX_DAG_ID='ETL_quarterly_performance_reports' AIRFLOW_CTX_TASK_ID='ingest_performance_reports_task' AIRFLOW_CTX_EXECUTION_DATE='2024-11-26T02:28:49.028749+00:00' AIRFLOW_CTX_TRY_NUMBER='1' AIRFLOW_CTX_DAG_RUN_ID='manual__2024-11-26T02:28:49.028749+00:00'
[2024-11-26T02:28:55.266+0000] {taskinstance.py:731} INFO - ::endgroup::
[2024-11-26T02:28:59.171+0000] {logging_mixin.py:190} INFO - Data successfully written to table AmountDescriptions.
[2024-11-26T02:28:59.630+0000] {logging_mixin.py:190} INFO - File moved from s3://project-processed-data/quarterly_performance_reports/amount_description_20241111_225350.csv to s3://project-processed-data/archived/quarterly_performance_reports/amount_description_20241111_225350.csv
[2024-11-26T02:29:00.894+0000] {taskinstance.py:3311} ERROR - Task failed with exception
Traceback (most recent call last):
  File "/home/airflow/.local/lib/python3.12/site-packages/airflow/models/taskinstance.py", line 767, in _execute_task
    result = _execute_callable(context=context, **execute_callable_kwargs)
             ^^^^^^^^^^^^^^^^^^^^^^^^^^^^^^^^^^^^^^^^^^^^^^^^^^^^^^^^^^^^^
  File "/home/airflow/.local/lib/python3.12/site-packages/airflow/models/taskinstance.py", line 733, in _execute_callable
    return ExecutionCallableRunner(
           ^^^^^^^^^^^^^^^^^^^^^^^^
  File "/home/airflow/.local/lib/python3.12/site-packages/airflow/utils/operator_helpers.py", line 252, in run
    return self.func(*args, **kwargs)
           ^^^^^^^^^^^^^^^^^^^^^^^^^^
  File "/home/airflow/.local/lib/python3.12/site-packages/airflow/models/baseoperator.py", line 417, in wrapper
    return func(self, *args, **kwargs)
           ^^^^^^^^^^^^^^^^^^^^^^^^^^^
  File "/home/airflow/.local/lib/python3.12/site-packages/airflow/operators/python.py", line 238, in execute
    return_value = self.execute_callable()
                   ^^^^^^^^^^^^^^^^^^^^^^^
  File "/home/airflow/.local/lib/python3.12/site-packages/airflow/operators/python.py", line 256, in execute_callable
    return runner.run(*self.op_args, **self.op_kwargs)
           ^^^^^^^^^^^^^^^^^^^^^^^^^^^^^^^^^^^^^^^^^^^
  File "/home/airflow/.local/lib/python3.12/site-packages/airflow/utils/operator_helpers.py", line 252, in run
    return self.func(*args, **kwargs)
           ^^^^^^^^^^^^^^^^^^^^^^^^^^
  File "/opt/airflow/dags/data_ingestion/quarterly_performance_reports_data_ingestion.py", line 96, in ingest_performance_reports
    file_1 = load_s3_file(source_bucket, performance_file)
             ^^^^^^^^^^^^^^^^^^^^^^^^^^^^^^^^^^^^^^^^^^^^^
  File "/opt/airflow/dags/helpers/aws_utils.py", line 51, in load_s3_file
    obj = s3.get_object(Bucket=bucket, Key=key)
          ^^^^^^^^^^^^^^^^^^^^^^^^^^^^^^^^^^^^^
  File "/home/airflow/.local/lib/python3.12/site-packages/botocore/client.py", line 569, in _api_call
    return self._make_api_call(operation_name, kwargs)
           ^^^^^^^^^^^^^^^^^^^^^^^^^^^^^^^^^^^^^^^^^^^
  File "/home/airflow/.local/lib/python3.12/site-packages/botocore/client.py", line 1023, in _make_api_call
    raise error_class(parsed_response, operation_name)
botocore.errorfactory.NoSuchKey: An error occurred (NoSuchKey) when calling the GetObject operation: The specified key does not exist.
[2024-11-26T02:29:00.940+0000] {taskinstance.py:1225} INFO - Marking task as FAILED. dag_id=ETL_quarterly_performance_reports, task_id=ingest_performance_reports_task, run_id=manual__2024-11-26T02:28:49.028749+00:00, execution_date=20241126T022849, start_date=20241126T022854, end_date=20241126T022900
[2024-11-26T02:29:00.958+0000] {taskinstance.py:340} INFO - ::group::Post task execution logs
[2024-11-26T02:29:00.959+0000] {standard_task_runner.py:124} ERROR - Failed to execute job 327 for task ingest_performance_reports_task (An error occurred (NoSuchKey) when calling the GetObject operation: The specified key does not exist.; 8298)
Traceback (most recent call last):
  File "/home/airflow/.local/lib/python3.12/site-packages/airflow/task/task_runner/standard_task_runner.py", line 117, in _start_by_fork
    ret = args.func(args, dag=self.dag)
          ^^^^^^^^^^^^^^^^^^^^^^^^^^^^^
  File "/home/airflow/.local/lib/python3.12/site-packages/airflow/cli/cli_config.py", line 49, in command
    return func(*args, **kwargs)
           ^^^^^^^^^^^^^^^^^^^^^
  File "/home/airflow/.local/lib/python3.12/site-packages/airflow/utils/cli.py", line 116, in wrapper
    return f(*args, **kwargs)
           ^^^^^^^^^^^^^^^^^^
  File "/home/airflow/.local/lib/python3.12/site-packages/airflow/cli/commands/task_command.py", line 483, in task_run
    task_return_code = _run_task_by_selected_method(args, _dag, ti)
                       ^^^^^^^^^^^^^^^^^^^^^^^^^^^^^^^^^^^^^^^^^^^^
  File "/home/airflow/.local/lib/python3.12/site-packages/airflow/cli/commands/task_command.py", line 256, in _run_task_by_selected_method
    return _run_raw_task(args, ti)
           ^^^^^^^^^^^^^^^^^^^^^^^
  File "/home/airflow/.local/lib/python3.12/site-packages/airflow/cli/commands/task_command.py", line 341, in _run_raw_task
    return ti._run_raw_task(
           ^^^^^^^^^^^^^^^^^
  File "/home/airflow/.local/lib/python3.12/site-packages/airflow/utils/session.py", line 97, in wrapper
    return func(*args, session=session, **kwargs)
           ^^^^^^^^^^^^^^^^^^^^^^^^^^^^^^^^^^^^^^
  File "/home/airflow/.local/lib/python3.12/site-packages/airflow/models/taskinstance.py", line 3005, in _run_raw_task
    return _run_raw_task(
           ^^^^^^^^^^^^^^
  File "/home/airflow/.local/lib/python3.12/site-packages/airflow/models/taskinstance.py", line 273, in _run_raw_task
    TaskInstance._execute_task_with_callbacks(
  File "/home/airflow/.local/lib/python3.12/site-packages/airflow/models/taskinstance.py", line 3159, in _execute_task_with_callbacks
    result = self._execute_task(context, task_orig)
             ^^^^^^^^^^^^^^^^^^^^^^^^^^^^^^^^^^^^^^
  File "/home/airflow/.local/lib/python3.12/site-packages/airflow/models/taskinstance.py", line 3183, in _execute_task
    return _execute_task(self, context, task_orig)
           ^^^^^^^^^^^^^^^^^^^^^^^^^^^^^^^^^^^^^^^
  File "/home/airflow/.local/lib/python3.12/site-packages/airflow/models/taskinstance.py", line 767, in _execute_task
    result = _execute_callable(context=context, **execute_callable_kwargs)
             ^^^^^^^^^^^^^^^^^^^^^^^^^^^^^^^^^^^^^^^^^^^^^^^^^^^^^^^^^^^^^
  File "/home/airflow/.local/lib/python3.12/site-packages/airflow/models/taskinstance.py", line 733, in _execute_callable
    return ExecutionCallableRunner(
           ^^^^^^^^^^^^^^^^^^^^^^^^
  File "/home/airflow/.local/lib/python3.12/site-packages/airflow/utils/operator_helpers.py", line 252, in run
    return self.func(*args, **kwargs)
           ^^^^^^^^^^^^^^^^^^^^^^^^^^
  File "/home/airflow/.local/lib/python3.12/site-packages/airflow/models/baseoperator.py", line 417, in wrapper
    return func(self, *args, **kwargs)
           ^^^^^^^^^^^^^^^^^^^^^^^^^^^
  File "/home/airflow/.local/lib/python3.12/site-packages/airflow/operators/python.py", line 238, in execute
    return_value = self.execute_callable()
                   ^^^^^^^^^^^^^^^^^^^^^^^
  File "/home/airflow/.local/lib/python3.12/site-packages/airflow/operators/python.py", line 256, in execute_callable
    return runner.run(*self.op_args, **self.op_kwargs)
           ^^^^^^^^^^^^^^^^^^^^^^^^^^^^^^^^^^^^^^^^^^^
  File "/home/airflow/.local/lib/python3.12/site-packages/airflow/utils/operator_helpers.py", line 252, in run
    return self.func(*args, **kwargs)
           ^^^^^^^^^^^^^^^^^^^^^^^^^^
  File "/opt/airflow/dags/data_ingestion/quarterly_performance_reports_data_ingestion.py", line 96, in ingest_performance_reports
    file_1 = load_s3_file(source_bucket, performance_file)
             ^^^^^^^^^^^^^^^^^^^^^^^^^^^^^^^^^^^^^^^^^^^^^
  File "/opt/airflow/dags/helpers/aws_utils.py", line 51, in load_s3_file
    obj = s3.get_object(Bucket=bucket, Key=key)
          ^^^^^^^^^^^^^^^^^^^^^^^^^^^^^^^^^^^^^
  File "/home/airflow/.local/lib/python3.12/site-packages/botocore/client.py", line 569, in _api_call
    return self._make_api_call(operation_name, kwargs)
           ^^^^^^^^^^^^^^^^^^^^^^^^^^^^^^^^^^^^^^^^^^^
  File "/home/airflow/.local/lib/python3.12/site-packages/botocore/client.py", line 1023, in _make_api_call
    raise error_class(parsed_response, operation_name)
botocore.errorfactory.NoSuchKey: An error occurred (NoSuchKey) when calling the GetObject operation: The specified key does not exist.
[2024-11-26T02:29:00.991+0000] {local_task_job_runner.py:266} INFO - Task exited with return code 1
[2024-11-26T02:29:01.007+0000] {taskinstance.py:3895} INFO - 0 downstream tasks scheduled from follow-on schedule check
[2024-11-26T02:29:01.010+0000] {local_task_job_runner.py:245} INFO - ::endgroup::
