[2024-11-23T05:21:54.189+0000] {local_task_job_runner.py:123} INFO - ::group::Pre task execution logs
[2024-11-23T05:21:54.206+0000] {taskinstance.py:2613} INFO - Dependencies all met for dep_context=non-requeueable deps ti=<TaskInstance: ETL_usa_spending.ingest_usa_spending_data_task manual__2024-11-23T05:21:47.910574+00:00 [queued]>
[2024-11-23T05:21:54.215+0000] {taskinstance.py:2613} INFO - Dependencies all met for dep_context=requeueable deps ti=<TaskInstance: ETL_usa_spending.ingest_usa_spending_data_task manual__2024-11-23T05:21:47.910574+00:00 [queued]>
[2024-11-23T05:21:54.216+0000] {taskinstance.py:2866} INFO - Starting attempt 1 of 1
[2024-11-23T05:21:54.231+0000] {taskinstance.py:2889} INFO - Executing <Task(PythonOperator): ingest_usa_spending_data_task> on 2024-11-23 05:21:47.910574+00:00
[2024-11-23T05:21:54.243+0000] {logging_mixin.py:190} WARNING - /home/***/.local/lib/python3.12/site-packages/***/task/task_runner/standard_task_runner.py:70 DeprecationWarning: This process (pid=86431) is multi-threaded, use of fork() may lead to deadlocks in the child.
[2024-11-23T05:21:54.244+0000] {standard_task_runner.py:72} INFO - Started process 86433 to run task
[2024-11-23T05:21:54.243+0000] {standard_task_runner.py:104} INFO - Running: ['***', 'tasks', 'run', 'ETL_usa_spending', 'ingest_usa_spending_data_task', 'manual__2024-11-23T05:21:47.910574+00:00', '--job-id', '192', '--raw', '--subdir', 'DAGS_FOLDER/project_dag.py', '--cfg-path', '/tmp/tmpo2h89mnm']
[2024-11-23T05:21:54.245+0000] {standard_task_runner.py:105} INFO - Job 192: Subtask ingest_usa_spending_data_task
[2024-11-23T05:21:54.297+0000] {task_command.py:467} INFO - Running <TaskInstance: ETL_usa_spending.ingest_usa_spending_data_task manual__2024-11-23T05:21:47.910574+00:00 [running]> on host 7da4b16cbed4
[2024-11-23T05:21:54.397+0000] {taskinstance.py:3132} INFO - Exporting env vars: AIRFLOW_CTX_DAG_OWNER='***' AIRFLOW_CTX_DAG_ID='ETL_usa_spending' AIRFLOW_CTX_TASK_ID='ingest_usa_spending_data_task' AIRFLOW_CTX_EXECUTION_DATE='2024-11-23T05:21:47.910574+00:00' AIRFLOW_CTX_TRY_NUMBER='1' AIRFLOW_CTX_DAG_RUN_ID='manual__2024-11-23T05:21:47.910574+00:00'
[2024-11-23T05:21:54.399+0000] {taskinstance.py:731} INFO - ::endgroup::
[2024-11-23T05:21:54.971+0000] {logging_mixin.py:190} INFO - Checking for new data to ingest into states
[2024-11-23T05:21:55.329+0000] {logging_mixin.py:190} WARNING - /opt/***/dags/helpers/db_utils.py:149 UserWarning: pandas only supports SQLAlchemy connectable (engine/connection) or database string URI or sqlite3 DBAPI2 connection. Other DBAPI2 objects are not tested. Please consider using SQLAlchemy.
[2024-11-23T05:21:55.423+0000] {logging_mixin.py:190} INFO - No new data to ingest for states
[2024-11-23T05:21:55.896+0000] {logging_mixin.py:190} INFO - Checking for new data to ingest into cfdaprograms
[2024-11-23T05:21:56.100+0000] {logging_mixin.py:190} WARNING - /opt/***/dags/helpers/db_utils.py:149 UserWarning: pandas only supports SQLAlchemy connectable (engine/connection) or database string URI or sqlite3 DBAPI2 connection. Other DBAPI2 objects are not tested. Please consider using SQLAlchemy.
[2024-11-23T05:21:56.163+0000] {taskinstance.py:3311} ERROR - Task failed with exception
Traceback (most recent call last):
  File "/home/airflow/.local/lib/python3.12/site-packages/airflow/models/taskinstance.py", line 767, in _execute_task
    result = _execute_callable(context=context, **execute_callable_kwargs)
             ^^^^^^^^^^^^^^^^^^^^^^^^^^^^^^^^^^^^^^^^^^^^^^^^^^^^^^^^^^^^^
  File "/home/airflow/.local/lib/python3.12/site-packages/airflow/models/taskinstance.py", line 733, in _execute_callable
    return ExecutionCallableRunner(
           ^^^^^^^^^^^^^^^^^^^^^^^^
  File "/home/airflow/.local/lib/python3.12/site-packages/airflow/utils/operator_helpers.py", line 252, in run
    return self.func(*args, **kwargs)
           ^^^^^^^^^^^^^^^^^^^^^^^^^^
  File "/home/airflow/.local/lib/python3.12/site-packages/airflow/models/baseoperator.py", line 417, in wrapper
    return func(self, *args, **kwargs)
           ^^^^^^^^^^^^^^^^^^^^^^^^^^^
  File "/home/airflow/.local/lib/python3.12/site-packages/airflow/operators/python.py", line 238, in execute
    return_value = self.execute_callable()
                   ^^^^^^^^^^^^^^^^^^^^^^^
  File "/home/airflow/.local/lib/python3.12/site-packages/airflow/operators/python.py", line 256, in execute_callable
    return runner.run(*self.op_args, **self.op_kwargs)
           ^^^^^^^^^^^^^^^^^^^^^^^^^^^^^^^^^^^^^^^^^^^
  File "/home/airflow/.local/lib/python3.12/site-packages/airflow/utils/operator_helpers.py", line 252, in run
    return self.func(*args, **kwargs)
           ^^^^^^^^^^^^^^^^^^^^^^^^^^
  File "/opt/airflow/dags/data_ingestion/usa_spending_data_ingestion.py", line 96, in ingest_usa_spending_data
    new_data_df = check_and_filter_new_data(df, table)
                  ^^^^^^^^^^^^^^^^^^^^^^^^^^^^^^^^^^^^
  File "/opt/airflow/dags/data_ingestion/usa_spending_data_ingestion.py", line 55, in check_and_filter_new_data
    merged_df = df.merge(existing_data, how='left', indicator=True)
                ^^^^^^^^^^^^^^^^^^^^^^^^^^^^^^^^^^^^^^^^^^^^^^^^^^^
  File "/home/airflow/.local/lib/python3.12/site-packages/pandas/core/frame.py", line 10487, in merge
    return merge(
           ^^^^^^
  File "/home/airflow/.local/lib/python3.12/site-packages/pandas/core/reshape/merge.py", line 169, in merge
    op = _MergeOperation(
         ^^^^^^^^^^^^^^^^
  File "/home/airflow/.local/lib/python3.12/site-packages/pandas/core/reshape/merge.py", line 804, in __init__
    self._maybe_coerce_merge_keys()
  File "/home/airflow/.local/lib/python3.12/site-packages/pandas/core/reshape/merge.py", line 1479, in _maybe_coerce_merge_keys
    raise ValueError(msg)
ValueError: You are trying to merge on float64 and object columns for key 'cfda_number'. If you wish to proceed you should use pd.concat
[2024-11-23T05:21:56.206+0000] {taskinstance.py:1225} INFO - Marking task as FAILED. dag_id=ETL_usa_spending, task_id=ingest_usa_spending_data_task, run_id=manual__2024-11-23T05:21:47.910574+00:00, execution_date=20241123T052147, start_date=20241123T052154, end_date=20241123T052156
[2024-11-23T05:21:56.228+0000] {taskinstance.py:340} INFO - ::group::Post task execution logs
[2024-11-23T05:21:56.229+0000] {standard_task_runner.py:124} ERROR - Failed to execute job 192 for task ingest_usa_spending_data_task (You are trying to merge on float64 and object columns for key 'cfda_number'. If you wish to proceed you should use pd.concat; 86433)
Traceback (most recent call last):
  File "/home/airflow/.local/lib/python3.12/site-packages/airflow/task/task_runner/standard_task_runner.py", line 117, in _start_by_fork
    ret = args.func(args, dag=self.dag)
          ^^^^^^^^^^^^^^^^^^^^^^^^^^^^^
  File "/home/airflow/.local/lib/python3.12/site-packages/airflow/cli/cli_config.py", line 49, in command
    return func(*args, **kwargs)
           ^^^^^^^^^^^^^^^^^^^^^
  File "/home/airflow/.local/lib/python3.12/site-packages/airflow/utils/cli.py", line 116, in wrapper
    return f(*args, **kwargs)
           ^^^^^^^^^^^^^^^^^^
  File "/home/airflow/.local/lib/python3.12/site-packages/airflow/cli/commands/task_command.py", line 483, in task_run
    task_return_code = _run_task_by_selected_method(args, _dag, ti)
                       ^^^^^^^^^^^^^^^^^^^^^^^^^^^^^^^^^^^^^^^^^^^^
  File "/home/airflow/.local/lib/python3.12/site-packages/airflow/cli/commands/task_command.py", line 256, in _run_task_by_selected_method
    return _run_raw_task(args, ti)
           ^^^^^^^^^^^^^^^^^^^^^^^
  File "/home/airflow/.local/lib/python3.12/site-packages/airflow/cli/commands/task_command.py", line 341, in _run_raw_task
    return ti._run_raw_task(
           ^^^^^^^^^^^^^^^^^
  File "/home/airflow/.local/lib/python3.12/site-packages/airflow/utils/session.py", line 97, in wrapper
    return func(*args, session=session, **kwargs)
           ^^^^^^^^^^^^^^^^^^^^^^^^^^^^^^^^^^^^^^
  File "/home/airflow/.local/lib/python3.12/site-packages/airflow/models/taskinstance.py", line 3005, in _run_raw_task
    return _run_raw_task(
           ^^^^^^^^^^^^^^
  File "/home/airflow/.local/lib/python3.12/site-packages/airflow/models/taskinstance.py", line 273, in _run_raw_task
    TaskInstance._execute_task_with_callbacks(
  File "/home/airflow/.local/lib/python3.12/site-packages/airflow/models/taskinstance.py", line 3159, in _execute_task_with_callbacks
    result = self._execute_task(context, task_orig)
             ^^^^^^^^^^^^^^^^^^^^^^^^^^^^^^^^^^^^^^
  File "/home/airflow/.local/lib/python3.12/site-packages/airflow/models/taskinstance.py", line 3183, in _execute_task
    return _execute_task(self, context, task_orig)
           ^^^^^^^^^^^^^^^^^^^^^^^^^^^^^^^^^^^^^^^
  File "/home/airflow/.local/lib/python3.12/site-packages/airflow/models/taskinstance.py", line 767, in _execute_task
    result = _execute_callable(context=context, **execute_callable_kwargs)
             ^^^^^^^^^^^^^^^^^^^^^^^^^^^^^^^^^^^^^^^^^^^^^^^^^^^^^^^^^^^^^
  File "/home/airflow/.local/lib/python3.12/site-packages/airflow/models/taskinstance.py", line 733, in _execute_callable
    return ExecutionCallableRunner(
           ^^^^^^^^^^^^^^^^^^^^^^^^
  File "/home/airflow/.local/lib/python3.12/site-packages/airflow/utils/operator_helpers.py", line 252, in run
    return self.func(*args, **kwargs)
           ^^^^^^^^^^^^^^^^^^^^^^^^^^
  File "/home/airflow/.local/lib/python3.12/site-packages/airflow/models/baseoperator.py", line 417, in wrapper
    return func(self, *args, **kwargs)
           ^^^^^^^^^^^^^^^^^^^^^^^^^^^
  File "/home/airflow/.local/lib/python3.12/site-packages/airflow/operators/python.py", line 238, in execute
    return_value = self.execute_callable()
                   ^^^^^^^^^^^^^^^^^^^^^^^
  File "/home/airflow/.local/lib/python3.12/site-packages/airflow/operators/python.py", line 256, in execute_callable
    return runner.run(*self.op_args, **self.op_kwargs)
           ^^^^^^^^^^^^^^^^^^^^^^^^^^^^^^^^^^^^^^^^^^^
  File "/home/airflow/.local/lib/python3.12/site-packages/airflow/utils/operator_helpers.py", line 252, in run
    return self.func(*args, **kwargs)
           ^^^^^^^^^^^^^^^^^^^^^^^^^^
  File "/opt/airflow/dags/data_ingestion/usa_spending_data_ingestion.py", line 96, in ingest_usa_spending_data
    new_data_df = check_and_filter_new_data(df, table)
                  ^^^^^^^^^^^^^^^^^^^^^^^^^^^^^^^^^^^^
  File "/opt/airflow/dags/data_ingestion/usa_spending_data_ingestion.py", line 55, in check_and_filter_new_data
    merged_df = df.merge(existing_data, how='left', indicator=True)
                ^^^^^^^^^^^^^^^^^^^^^^^^^^^^^^^^^^^^^^^^^^^^^^^^^^^
  File "/home/airflow/.local/lib/python3.12/site-packages/pandas/core/frame.py", line 10487, in merge
    return merge(
           ^^^^^^
  File "/home/airflow/.local/lib/python3.12/site-packages/pandas/core/reshape/merge.py", line 169, in merge
    op = _MergeOperation(
         ^^^^^^^^^^^^^^^^
  File "/home/airflow/.local/lib/python3.12/site-packages/pandas/core/reshape/merge.py", line 804, in __init__
    self._maybe_coerce_merge_keys()
  File "/home/airflow/.local/lib/python3.12/site-packages/pandas/core/reshape/merge.py", line 1479, in _maybe_coerce_merge_keys
    raise ValueError(msg)
ValueError: You are trying to merge on float64 and object columns for key 'cfda_number'. If you wish to proceed you should use pd.concat
[2024-11-23T05:21:56.268+0000] {local_task_job_runner.py:266} INFO - Task exited with return code 1
[2024-11-23T05:21:56.288+0000] {taskinstance.py:3895} INFO - 0 downstream tasks scheduled from follow-on schedule check
[2024-11-23T05:21:56.290+0000] {local_task_job_runner.py:245} INFO - ::endgroup::
